Workbook
Name arp: #REF!
Name arp: #REF!
Name arp: #REF!
Name Riesgo: #REF!
Name Riesgo: #REF!
Name Riesgo: #REF!

Sheet PLATOS
C1: TALLER COSTOS
C2: VERSIÓN 3
C3: 44802
C4: ALMA RURAL
A5: INICIA EL DIA EN EL CAMPO | C5: COSTO | D5: PRECIO DE VENTA | E5: % DE COSTO
A6: 1 | B6: =+'ESTANDAR CAMPO'!A1 -> CAMPESINO | C6: =+'ESTANDAR CAMPO'!F14 -> 10492.311 | D6: 33000 | E6: =+C6/D6 -> 0.31794883
A7: =1+A6 -> 2 | B7: HUEVOS EN CACEROLA | C7: =+'ESTANDAR CAMPO'!F40 -> 5599.4442 | D7: 24000 | E7: =+C7/D7 -> 0.23331017
A8: =1+A7 -> 3 | B8: HUEVOS NAPOLITANOS | C8: =+'ESTANDAR CAMPO'!F66 -> 10381.882 | D8: 24000 | E8: =+C8/D8 -> 0.4325784
A9: =1+A8 -> 4 | B9: HUEVOS AL GUSTO | C9: =+'ESTANDAR CAMPO'!F92 -> 6606.1867 | D9: 25000 | E9: =+C9/D9 -> 0.26424747
A10: =1+A9 -> 5 | B10: OMELETTE | C10: =+'ESTANDAR CAMPO'!F92 -> 6606.1867 | D10: 28000 | E10: =+C10/D10 -> 0.23593524
A12: DESAYUNOS SALUABLES | C12: COSTO | D12: COSTO MAX | E12: % DE COSTO
A13: 6 | B13: BOWL NUTRITIVO | C13: =+'ESTANDAR SALUDABLE'!F11 -> 8428.4 | D13: 20000 | E13: =+C13/D13 -> 0.42142
A14: =1+A13 -> 7 | B14: WAFFLE | C14: =+'ESTANDAR SALUDABLE'!F34 -> 12612.755 | D14: 20000 | E14: =+C14/D14 -> 0.63063775
A15: =1+A14 -> 8 | B15: BATIDO VERDE | C15: =+'ESTANDAR SALUDABLE'!F53 -> 5247 | D15: 15000 | E15: =+C15/D15 -> 0.3498
A17: ENTRADAS DE LA HUERTA | C17: COSTO | D17: COSTO MAX | E17: % DE COSTO
A18: 9 | B18: PATACONAS DE LAS MONTAÑAS COLOMBIANAS | C18: =+'ESTANDAR ENTRADAS'!F10 -> 8117.3731 | D18: 14000 | E18: =+C18/D18 -> 0.57981236
A19: =1+A18 -> 10 | B19: DULCE TENTACIÓN ABORRAJADA | C19: =+'ESTANDAR ENTRADAS'!F31 -> 4219.1 | D19: 20000 | E19: =+C19/D19 -> 0.210955
A20: =1+A19 -> 11 | B20: CHICHARRON CAMPESINO | C20: =+'ESTANDAR ENTRADAS'!F58 -> 20268.461 | D20: 28000 | E20: =+C20/D20 -> 0.72387362 | F20: REVISAR VALORES DE RECETA
A22: AVES DEL CORRAL | C22: COSTO | D22: COSTO MAX | E22: % DE COSTO
A23: 12 | B23: BROCHETAS DE POLLO A LA BRASA | C23: =+'AVES DEL CORRAL'!F12 -> 13392.241 | D23: 30000 | E23: =+C23/D23 -> 0.44640803
A24: =1+A23 -> 13 | B24: POLLO CRIOLLO SALTEADO | C24: =+'AVES DEL CORRAL'!F37 -> 14436.711 | D24: 38000 | E24: =+C24/D24 -> 0.37991344
A25: =1+A24 -> 14 | B25: PECHUGA DE POLLO A LA PARRILLA | C25: =+'AVES DEL CORRAL'!F60 -> 13150.881 | D25: 34000 | E25: =+C25/D25 -> 0.38679062
A26: =1+A25 -> 15 | B26: PECHUGA DE POLLO EN SALSA DE CHAMPIÑONES | C26: =+'AVES DEL CORRAL'!F84 -> 16649.607 | D26: 38000 | E26: =+C26/D26 -> 0.43814755
A28: SABORES DEL CERDO | C28: COSTO | D28: PRECIO DE VENTA | E28: % DE COSTO
A29: 16 | B29: COSTILLAS DE CERDO BBQ | C29: =+'SABORES DE CERDO'!F15 -> 15004.539 | D29: 40000 | E29: 0.38
A31: TESOROS DEL RIO | C31: COSTO | D31: PRECIO DE VENTA | E31: % DE COSTO
A32: 17 | B32: TRUCHA AHUMADA DE LA HUERTA | C32: =+'TESOROS DEL RIO'!F18 -> 16193.544 | D32: 38000 | E32: =+C32/D32 -> 0.42614591
A33: =+A32+1 -> 18 | B33: TRUCHA A LA CRIOLLA | C33: =+'TESOROS DEL RIO'!F44 -> 17423.273 | D33: 39000 | E33: =+C33/D33 -> 0.44675059
A34: =+A33+1 -> 19 | B34: TRUCHA CON CHAMPIÑONES | C34: =+'TESOROS DEL RIO'!F70 -> 15260.446 | D34: 42000 | E34: =+C34/D34 -> 0.36334396
A35: =+A34+1 -> 20 | B35: TRUCHA AL AJILLO | C35: =+'TESOROS DEL RIO'!F98 -> 18707.759 | D35: 40000 | E35: =+C35/D35 -> 0.46769398
A36: =+A35+1 -> 21 | B36: TRUCHA CON ALMENDRAS | C36: =+'TESOROS DEL RIO'!F126 -> 20083.359 | D36: 43000 | E36: =+C36/D36 -> 0.46705486
A37: =+A36+1 -> 22 | B37: TRUCHA DE COCO | C37: =+'TESOROS DEL RIO'!F155 -> 22267.546 | D37: 45000 | E37: =+C37/D37 -> 0.49483434
A38: =+A37+1 -> 23 | B38: TRUCHA TROPICAL | C38: =+'TESOROS DEL RIO'!F185 -> 25039.142 | D38: 45000 | E38: =+C38/D38 -> 0.55642538
A40: CARNES DEL CORRAL | C40: COSTO | D40: PRECIO DE VENTA | E40: % DE COSTO
A41: 24 | B41: CHURRASCO DE RES | C41: =+'CARNE DEL CORRAL'!F15 -> 20567.197 | D41: 43000 | E41: =+C41/D41 -> 0.4783069
A42: =+A41+1 -> 25 | B42: PUNTA DE ANCA ASADA | C42: =+'CARNE DEL CORRAL'!F40 -> 22333.432 | D42: 44000 | E42: =+C42/D42 -> 0.507578
A43: =+A42+1 -> 26 | B43: CORDERO AHUMADO | C43: =+'CARNE DEL CORRAL'!F68 -> 5006.5554 | D43: 60000 | E43: =+C43/D43 -> 0.083442591 | F43: FALTAN INGREDIENTES
A44: =+A43+1 -> 27 | B44: HAMBURGUESA ARTESANAL DE LA CASA | C44: =+'CARNE DEL CORRAL'!F94 -> 10498.627 | D44: 29000 | E44: =+C44/D44 -> 0.36202164
A45: =+A44+1 -> 28 | B45: HAMBURGUESA ANGUS PREMIUM | C45: =+'CARNE DEL CORRAL'!F122 -> 6744.774 | D45: 38000 | E45: =+C45/D45 -> 0.17749405 | F45: FALTAN INGREDIENTES
A46: =+A45+1 -> 29 | B46: HAMBURGUESA DE CORDERO | C46: =+'CARNE DEL CORRAL'!F148 -> 6744.774 | D46: 38000 | E46: =+C46/D46 -> 0.17749405 | F46: FALTAN INGREDIENTES
...

Sheet LISTA MAESTRA
C1: TALLER COSTOS
C2: VERSIÓN 3 | G2: UNIDADES DE MEDIDA | H2: SIMBOLO
C3: 44802 | G3: GRAMOS | H3: GR | I3: UNIDADES DE MEDIDA PARA PESO
C4: ALMA RURAL | G4: LIBRAS | H4: LB
A5: CARNES ROJAS | B5: UND/M | C5: PRECIO COMPRA | D5: COSTO GR | E5: V/ PORCIÓN | G5: KILOGRAMOS | H5: KL
A6: PUNTA DE ANCA | B6: KL | C6: 48800 | D6: =+C6/1000 -> 48.8 | G6: CENTIMETROS CUBICOS | H6: CC | I6: UNIDADES DE MEDIDA PARA VOLUMEN
A7: LOMO ANCHO | B7: KL | C7: 44000 | D7: =+C7/1000 -> 44 | G7: LITROS | H7: LTS
A8: MURILLO PIERNA | B8: KL | C8: 23600 | D8: =+C8/1000 -> 23.6 | G8: UNIDADES | H8: UND | I8: VALOR INDIVIDUAL
A9: HUESO DE COGOTE | B9: KL | C9: 10710 | D9: =+C9/1000 -> 10.71
A10: PECHO KILO | B10: KL | C10: 27600 | D10: =+C10/1000 -> 27.6
A11: MORRILLO KILO | B11: KL | C11: 24000 | D11: =+C11/1000 -> 24
A13: PESCADOS Y MARISCOS | B13: UND/M | C13: PRECIO COMPRA | D13: COSTO und | E13: V/ PORCIÓN
A14: TRUCHA | B14: KL | C14: 229680 | D14: =+C14/20 -> 11484
A15: CAMARON CRUDO | B15: UND | C15: 850 | D15: =+C15/1 -> 850
A20: CERDO | B20: UND/M | C20: PRECIO COMPRA | D20: COSTO GR | E20: V/ PORCIÓN
A21: COSTILLA DE CERDO | B21: KL | C21: 23600 | D21: =+C21/1000 -> 23.6
A22: TOCINO BARRIGUERO | B22: KL | C22: 22000 | D22: =+C22/1000 -> 22
A23: TOCINO CARNUDO | B23: KL | C23: 28000 | D23: =+C23/1000 -> 28
A24: PAPADA | B24: KL | C24: 19000 | D24: =+C24/1000 -> 19
A25: JAMON RICA | B25: GR | C25: 8400 | D25: =+C25/15 -> 560
A26: PERNIL CERDO | B26: GR | C26: 23600 | D26: =+C26/1000 -> 23.6
A27: TOCINETA AHUMADA X250 | B27: GR | C27: 6600 | D27: =+C27/10 -> 660
A29: POLLO | B29: UND/M | C29: PRECIO COMPRA | D29: COSTO GR | E29: V/ PORCIÓN
A30: PECHUGA DE POLLO | B30: KL | C30: 23400 | D30: =+C30/1000 -> 23.4
A31: ALAS DE POLLO | B31: KL | C31: 16400 | D31: =+C31/1000 -> 16.4
A32: VERDURAS | B32: UND/M | C32: PRECIO COMPRA | D32: COSTO GR | E32: V/ PORCIÓN
A33: MAZORCA CHOCLO | B33: GR | C33: 6500 | D33: =+C33/1000 -> 6.5
A34: PAPA CRIOLLA | B34: GR | C34: 6800 | D34: =+C34/1000 -> 6.8
A35: YUCA | B35: GR | C35: 5700 | D35: =+C35/1000 -> 5.7
A36: LECHUGA BATAVIA | B36: GR | C36: 2200 | D36: =+C36/250 -> 8.8
A37: AGUACATE | B37: GR | C37: 12000 | D37: =+C37/1000 -> 12
A38: AREPAS PQT X 10 | B38: UN | C38: 1000 | D38: =+C38/10 -> 100
A39: HUEVO AA | B39: UND | C39: 13000 | D39: =+C39/30 -> 433.33333
A40: CHAMPIÑON | B40: GR | C40: 14800 | D40: =+C40/500 -> 29.6
A41: ESPINACA | B41: GR | C41: 3400 | D41: =+C41/200 -> 17
A42: APIO | B42: ATADO | C42: 3000 | D42: =+C42/250 -> 12
A43: PAPA PASTUSA | B43: KL | C43: 2900 | D43: =+C43/1000 -> 2.9
A44: MALLA DE AJO | B44: 125 | C44: 1100 | D44: =+C44/50 -> 22
A45: CEBOLLA LARGA | B45: LB | C45: 3400 | D45: =+C45/500 -> 6.8
A46: TOMATE CHONTO | B46: KL | C46: 3200 | D46: =+C46/1000 -> 3.2
...

Sheet RECETA BASE
A1: CALDO DE ALAS
A2: RECETAS ESTANDAR ALMA RURAL 2025
E3: RECETA # | F3: 1
E4: # PORCIONES | F4: 1
A5: COD. | B5: INGREDIENTES | C5: UNID | D5: CANT. | E5: V/UNIT. | F5: V/TOTAL
B6: ALAS | C6: UND | D6: 1 | E6: =+'LISTA MAESTRA'!D31 -> 16.4 | F6: =E6*D6 -> 16.4
B7: PAPA CRIOLLA | C7: GR | D7: 150 | E7: =+'LISTA MAESTRA'!D34 -> 6.8 | F7: =E7*D7 -> 1020
B8: PAPA PASTUSA | C8: UND | D8: 200 | E8: =+'LISTA MAESTRA'!D43 -> 2.9 | F8: =E8*D8 -> 580
B9: CILANTRO | C9: GR | D9: 10 | E9: =+'LISTA MAESTRA'!D62 -> 3.4 | F9: =E9*D9 -> 34
B10: AJO | C10: GR | D10: 2 | E10: =+'LISTA MAESTRA'!D44 -> 22 | F10: =E10*D10 -> 44
B11: SAL | C11: GR | D11: 2 | E11: =+'LISTA MAESTRA'!D95 -> 2.4666667 | F11: =E11*D11 -> 4.9333333
B12: CILANTRON | C12: GR | D12: 10 | E12: =+'LISTA MAESTRA'!D63 -> 51.666667 | F12: =E12*D12 -> 516.66667
A14: COSTO TOTAL DE LOS INGREDIENTES | F14: =SUM(F6:F13) -> 2216
A15: MARGEN DE ERROR O VARIACIÓN | E15: 0.06 | F15: =+F14*E15 -> 132.96
A16: COSTO DE UNA PORCION + EL MARGEN DE ERROR | F16: =+F14+F15 -> 2348.96
A17: COSTO TOTAL DE UNA PORCION | F17: =+F14/F4 -> 2216
A18: COSTO TOTAL DE LOS INGREDIENTES | F18: =ROUND(F17, -2) -> 2200
A21: HUEVOS CRIOLLOS
A22: RECETAS ESTANDAR ALMA RURAL 2025
E23: RECETA # | F23: 2
E24: # PORCIONES | F24: 1
A25: COD. | B25: INGREDIENTES | C25: UNID | D25: CANT. | E25: V/UNIT. | F25: V/TOTAL
B26: HUEVO | C26: UND | D26: 2 | E26: =+'LISTA MAESTRA'!D39 -> 433.33333 | F26: =E26*D26 -> 866.66667
B27: CEBOLLA LARGA | C27: GR | D27: 20 | E27: =+'LISTA MAESTRA'!D45 -> 6.8 | F27: =E27*D27 -> 136
B28: TOMATE CHONTO | C28: GR | D28: 150 | E28: =+'LISTA MAESTRA'!D46 -> 3.2 | F28: =E28*D28 -> 480
B29: MARGARINA | C29: GR | D29: 60 | E29: =+'LISTA MAESTRA'!D87 -> 17.2625 | F29: =E29*D29 -> 1035.75
B30: SAL | C30: GR | D30: 1 | E30: =+'LISTA MAESTRA'!D95 -> 2.4666667 | F30: =E30*D30 -> 2.4666667
F31: =E31*D31 -> 0
A32: COSTO TOTAL DE LOS INGREDIENTES | F32: =SUM(F26:F31) -> 2520.8833
A33: MARGEN DE ERROR O VARIACIÓN | E33: 0.06 | F33: =+F32*E33 -> 151.253
A34: COSTO DE UNA PORCION + EL MARGEN DE ERROR | F34: =+F32+F33 -> 2672.1363
A35: COSTO TOTAL DE UNA PORCION | F35: =+F32/F24 -> 2520.8833
A36: COSTO TOTAL DE LOS INGREDIENTES | F36: =+F34 -> 2672.1363
A39: WAFFLES
A40: RECETAS ESTANDAR ALMA RURAL 2025
E41: RECETA #
E42: # PORCIONES | F42: 2
A43: COD. | B43: INGREDIENTES | C43: UNID | D43: CANT. | E43: V/UNIT. | F43: V/TOTAL
B44: HARINA DE TRIGO | C44: GR | D44: 60 | E44: =+'LISTA MAESTRA'!D96 -> 3.4 | F44: =+E44*D44 -> 204
B45: HARINA DE YUCA | C45: GR | D45: 30 | E45: =+'LISTA MAESTRA'!D97 -> 39 | F45: =+E45*D45 -> 1170
...

Sheet ESTANDAR CAMPO
A1: CAMPESINO
A2: RECETAS ESTANDAR ALMA RURAL 2025 | H2: LISTA MAESTRA | I2: 'RECETA BASE'
A3: : | E3: # RECETA | F3: 1
E4: # PORCIONES | F4: 1
A5: COD. | B5: INGREDIENTES | C5: UNID | D5: CANT. | E5: V/UNIT. | F5: V/TOTAL
B6: CALDO DE ALAS | C6: PORCION | D6: 1 | E6: =+'RECETA BASE'!F16 -> 2348.96 | F6: =+E6*D6 -> 2348.96
B7: HUEVOS CRIOLLOS | C7: PORCION | D7: 1 | E7: =+'RECETA BASE'!F34 -> 2672.1363 | F7: =+E7*D7 -> 2672.1363
B8: AREPA | C8: UND | D8: 1 | E8: =+'LISTA MAESTRA'!D38 -> 100 | F8: =+E8*D8 -> 100
B9: QUESO CRIOLLO | C9: GR | D9: 50 | E9: =+'LISTA MAESTRA'!D74 -> 23.4 | F9: =+E9*D9 -> 1170
B10: WAFFLE MEDIA PORCION | C10: PORC | D10: 1 | E10: =+'RECETA BASE'!F59 -> 1435.14 | F10: =+E10*D10 -> 1435.14
B11: BEBIDA DE ELECCIÓN | C11: PORC | D11: 1 | E11: =+'RECETA BASE'!F73 -> 1684.075 | F11: =+E11*D11 -> 1684.075
B12: BIZCOCHOS | C12: UND | D12: 5 | E12: =+'LISTA MAESTRA'!D111 -> 216.4 | F12: =+E12*D12 -> 1082
A14: COSTO TOTAL DE LOS INGREDIENTES | F14: =SUM(F6:F13) -> 10492.311
A15: MARGEN DE ERROR O VARIACIÓN | E15: 0 | F15: =+F14*E15 -> 0
A16: COSTO TOTAL DE LA PREPARACIÓN + MARGEN DE ERROR | F16: =+F14+F15 -> 10492.311
A17: COSTO DE UNA PORCIÓN SUMANDO EL MARGEN DE ERROR | F17: =+F16/F4 -> 10492.311
A18: % COSTO MATERIA PRIMA ESTABLECIDO POR GERENCIA | F18: 0.35
A19: PRECIO POTENCIAL DE VENTA DE UNA PORCIÓN | F19: =+F17/F18 -> 29978.032
A20: PRECIO REAL DE VENTA DE UNA PORCIÓN | F20: =ROUNDUP(F19,-2) -> 30000
A21: % REAL DE COSTO (COSTO PORCIÓN SOBRE PRECIO REAL VENTA) | F21: =+F17/F20 -> 0.34974371
A22: IVA GENERADO AL VENDER CADA PORCIÓN | E22: 0.08 | F22: =+F20*E22 -> 2400
A23: PRECIO PARA LA CARTA DE CADA PORCIÓN | F23: =+F20+F22 -> 32400
A26: HUEVOS EN CACEROLA
A27: RECETAS ESTANDAR ALMA RURAL 2025
A28: : | E28: # RECETA | F28: 2
E29: # PORCIONES | F29: 1
A30: COD. | B30: INGREDIENTES | C30: UNID | D30: CANT. | E30: V/UNIT. | F30: V/TOTAL
B31: HUEVO | C31: UND | D31: 2 | E31: =+'LISTA MAESTRA'!D39 -> 433.33333 | F31: =E31*D31 -> 866.66667
B32: MARGARINA | C32: GR | D32: 25 | E32: =+'LISTA MAESTRA'!D87 -> 17.2625 | F32: =E32*D32 -> 431.5625
B33: VEGETALES DE LA HUERTA | F33: =E33*D33 -> 0
B34: BEBIDA DE ELECCIÓN | C34: PORC | D34: 1 | E34: =+'RECETA BASE'!F73 -> 1684.075 | F34: =E34*D34 -> 1684.075
B35: AREPA | C35: UND | D35: 1 | E35: =+'LISTA MAESTRA'!D38 -> 100 | F35: =E35*D35 -> 100
B36: BIZCOCHOS DE ACHIRA | C36: UND | D36: 5 | E36: =+'LISTA MAESTRA'!D111 -> 216.4 | F36: =E36*D36 -> 1082
B37: WAFLE MEDIA PORCION | C37: PORC | D37: 1 | E37: =+'RECETA BASE'!F59 -> 1435.14 | F37: =E37*D37 -> 1435.14
F38: =E38*D38 -> 0
F39: =E39*D39 -> 0
A40: COSTO TOTAL DE LOS INGREDIENTES | F40: =SUM(F31:F39) -> 5599.4442
A41: MARGEN DE ERROR O VARIACIÓN | E41: 0 | F41: =+F40*E41 -> 0
A42: COSTO TOTAL DE LA PREPARACIÓN + MARGEN DE ERROR | F42: =+F40+F41 -> 5599.4442
A43: COSTO DE UNA PORCIÓN SUMANDO EL MARGEN DE ERROR | F43: =+F42/F29 -> 5599.4442
...

Sheet ESTANDAR SALUDABLE
A1: BOWL NUTRITIVO
A2: RECETAS ESTANDAR ALMA RURAL 2025 | H2: LISTA MAESTRA | I2: 'RECETA BASE'
A3: : | E3: # RECETA | F3: 6
E4: # PORCIONES | F4: 1
A5: COD. | B5: INGREDIENTES | C5: UNID | D5: CANT. | E5: V/UNIT. | F5: V/TOTAL
B6: YOGURT TARRITO | C6: UND | D6: 1 | E6: =+'LISTA MAESTRA'!D76 -> 2500 | F6: =+E6*D6 -> 2500
B7: FRUTAS | C7: PORC | D7: 1 | E7: =+'RECETA BASE'!F216 -> 4388.4 | F7: =+E7*D7 -> 4388.4
B8: GRANOLA | C8: GR | D8: 100 | E8: =+'LISTA MAESTRA'!D112 -> 15.4 | F8: =+E8*D8 -> 1540
F9: =+E9*D9 -> 0
A11: COSTO TOTAL DE LOS INGREDIENTES | F11: =SUM(F6:F10) -> 8428.4
A12: MARGEN DE ERROR O VARIACIÓN | E12: 0 | F12: =+F11*E12 -> 0
A13: COSTO TOTAL DE LA PREPARACIÓN + MARGEN DE ERROR | F13: =+F11+F12 -> 8428.4
A14: COSTO DE UNA PORCIÓN SUMANDO EL MARGEN DE ERROR | F14: =+F13/F4 -> 8428.4
A15: % COSTO MATERIA PRIMA ESTABLECIDO POR GERENCIA | F15: 0.35
A16: PRECIO POTENCIAL DE VENTA DE UNA PORCIÓN | F16: =+F14/F15 -> 24081.143
A17: PRECIO REAL DE VENTA DE UNA PORCIÓN | F17: =ROUNDUP(F16,-2) -> 24100
A18: % REAL DE COSTO (COSTO PORCIÓN SOBRE PRECIO REAL VENTA) | F18: =+F14/F17 -> 0.34972614
A19: IVA GENERADO AL VENDER CADA PORCIÓN | E19: 0.08 | F19: =+F17*E19 -> 1928
A20: PRECIO PARA LA CARTA DE CADA PORCIÓN | F20: =+F17+F19 -> 26028
A23: WAFFLES
A24: RECETAS ESTANDAR ALMA RURAL 2025
A25: : | E25: # RECETA | F25: 7
E26: # PORCIONES | F26: 1
A27: COD. | B27: INGREDIENTES | C27: UNID | D27: CANT. | E27: V/UNIT. | F27: V/TOTAL
B28: WAFLES COMPLETO | C28: UND | D28: 1 | E28: =+'RECETA BASE'!F56 -> 2870.28 | F28: =E28*D28 -> 2870.28
B29: YOGURT | C29: UND | D29: 1 | E29: =+'LISTA MAESTRA'!D76 -> 2500 | F29: =E29*D29 -> 2500
B30: BEBIDA CALIENTE | C30: PORCION | D30: 1 | E30: =+'RECETA BASE'!F73 -> 1684.075 | F30: =E30*D30 -> 1684.075
B31: FRUTAS | C31: PORCION | D31: 1 | E31: =+'RECETA BASE'!F216 -> 4388.4 | F31: =E31*D31 -> 4388.4
B32: QUESO CRIOLLO | C32: PORCION | D32: 50 | E32: =+'LISTA MAESTRA'!D74 -> 23.4 | F32: =E32*D32 -> 1170
B33: MERMELADA MORA O UCHUVA | C33: PORCION | D33: 1 | F33: =E33*D33 -> 0
A34: COSTO TOTAL DE LOS INGREDIENTES | F34: =SUM(F28:F33) -> 12612.755
A35: MARGEN DE ERROR O VARIACIÓN | E35: 0 | F35: =+F34*E35 -> 0
A36: COSTO TOTAL DE LA PREPARACIÓN + MARGEN DE ERROR | F36: =+F34+F35 -> 12612.755
A37: COSTO DE UNA PORCIÓN SUMANDO EL MARGEN DE ERROR | F37: =+F36/F26 -> 12612.755
A38: % COSTO MATERIA PRIMA ESTABLECIDO POR GERENCIA | F38: 0.35
A39: PRECIO POTENCIAL DE VENTA DE UNA PORCIÓN | F39: =+F37/F38 -> 36036.443
A40: PRECIO REAL DE VENTA DE UNA PORCIÓN | F40: =ROUNDUP(F39,-2) -> 36100
A41: % REAL DE COSTO (COSTO PORCIÓN SOBRE PRECIO REAL VENTA) | F41: =+F37/F40 -> 0.3493838
A42: IVA GENERADO AL VENDER CADA PORCIÓN | E42: 0.08 | F42: =+F40*E42 -> 2888
A43: PRECIO PARA LA CARTA DE CADA PORCIÓN | F43: =+F40+F42 -> 38988
...

Sheet ESTANDAR ENTRADAS
A1: PATACONES DE LAS MONTAÑAS COLOMBIANAS
A2: RECETAS ESTANDAR ALMA RURAL 2025 | H2: LISTA MAESTRA | I2: 'RECETA BASE'
A3: : | E3: # RECETA | F3: 9
E4: # PORCIONES | F4: 1
A5: COD. | B5: INGREDIENTES | C5: UNID | D5: CANT. | E5: V/UNIT. | F5: V/TOTAL
B6: PLATANO VERDE | C6: PORC | D6: 1 | E6: =+'RECETA BASE'!F107 -> 4971.824 | F6: =+E6*D6 -> 4971.824
B7: SALSA CRIOLLA | C7: PORC | D7: 1 | E7: =+'RECETA BASE'!F252 -> 805.54906 | F7: =+E7*D7 -> 805.54906
B8: QUESO CRIOLLO | C8: GR | D8: 100 | E8: =+'LISTA MAESTRA'!D74 -> 23.4 | F8: =+E8*D8 -> 2340
A10: COSTO TOTAL DE LOS INGREDIENTES | F10: =SUM(F6:F9) -> 8117.3731
A11: MARGEN DE ERROR O VARIACIÓN | E11: 0 | F11: =+F10*E11 -> 0
A12: COSTO TOTAL DE LA PREPARACIÓN + MARGEN DE ERROR | F12: =+F10+F11 -> 8117.3731
A13: COSTO DE UNA PORCIÓN SUMANDO EL MARGEN DE ERROR | F13: =+F12/F4 -> 8117.3731
A14: % COSTO MATERIA PRIMA ESTABLECIDO POR GERENCIA | F14: 0.35
A15: PRECIO POTENCIAL DE VENTA DE UNA PORCIÓN | F15: =+F13/F14 -> 23192.494
A16: PRECIO REAL DE VENTA DE UNA PORCIÓN | F16: =ROUNDUP(F15,-2) -> 23200
A17: % REAL DE COSTO (COSTO PORCIÓN SOBRE PRECIO REAL VENTA) | F17: =+F13/F16 -> 0.34988677
A18: IVA GENERADO AL VENDER CADA PORCIÓN | E18: 0.08 | F18: =+F16*E18 -> 1856
A19: PRECIO PARA LA CARTA DE CADA PORCIÓN | F19: =+F16+F18 -> 25056
A22: DULCE TENTACION ABORRAJADA
A23: RECETAS ESTANDAR ALMA RURAL 2025
A24: : | E24: # RECETA | F24: 10
E25: # PORCIONES | F25: 1
A26: COD. | B26: INGREDIENTES | C26: UNID | D26: CANT. | E26: V/UNIT. | F26: V/TOTAL
B27: ABORRAJADO | C27: PORCI | D27: 3 | E27: =+'RECETA BASE'!F128 -> 1305.9667 | F27: =E27*D27 -> 3917.9
B28: BOCADILLO | C28: GR | D28: 20 | E28: =+'LISTA MAESTRA'!D113 -> 15.06 | F28: =E28*D28 -> 301.2
F30: 0
A31: COSTO TOTAL DE LOS INGREDIENTES | F31: =SUM(F27:F30) -> 4219.1
A32: MARGEN DE ERROR O VARIACIÓN | E32: 0 | F32: =+F31*E32 -> 0
A33: COSTO TOTAL DE LA PREPARACIÓN + MARGEN DE ERROR | F33: =+F31+F32 -> 4219.1
A34: COSTO DE UNA PORCIÓN SUMANDO EL MARGEN DE ERROR | F34: =+F33/F25 -> 4219.1
A35: % COSTO MATERIA PRIMA ESTABLECIDO POR GERENCIA | F35: 0.35
A36: PRECIO POTENCIAL DE VENTA DE UNA PORCIÓN | F36: =+F34/F35 -> 12054.571
A37: PRECIO REAL DE VENTA DE UNA PORCIÓN | F37: =ROUNDUP(F36,-2) -> 12100
A38: % REAL DE COSTO (COSTO PORCIÓN SOBRE PRECIO REAL VENTA) | F38: =+F34/F37 -> 0.34868595
A39: IVA GENERADO AL VENDER CADA PORCIÓN | E39: 0.08 | F39: =+F37*E39 -> 968
A40: PRECIO PARA LA CARTA DE CADA PORCIÓN | F40: =+F37+F39 -> 13068
A43: CHICHARRON CAMPESINO
A44: RECETAS ESTANDAR ALMA RURAL 2025
A45: : | E45: # RECETA | F45: 11
E46: # PORCIONES | F46: 1
...

Sheet AVES DEL CORRAL
A1: BROCHETAS DE POLLO A LA BRASA
A2: RECETAS ESTANDAR ALMA RURAL 2025 | H2: LISTA MAESTRA | I2: 'RECETA BASE'
A3: : | E3: # RECETA | F3: 12
E4: # PORCIONES | F4: 1
A5: COD. | B5: INGREDIENTES | C5: UNID | D5: CANT. | E5: V/UNIT. | F5: V/TOTAL
B6: BROCHETA PORCION | C6: PORCION | D6: 2 | E6: =+'RECETA BASE'!F165 -> 5093.851 | F6: =+E6*D6 -> 10187.702
B7: PORCION ENSALADA | C7: PORCION | D7: 1 | E7: =+'RECETA BASE'!F331 -> 1020.515 | F7: =+E7*D7 -> 1020.515
B8: PAPAS EN CASCO | C8: PORCION | D8: 1 | E8: =+'RECETA BASE'!F142 -> 2184.024 | F8: =+E8*D8 -> 2184.024
B9: ALIOLI | C9: PORCION | D9: 1 | F9: =+E9*D9 -> 0
B10: SALSA DE UCHUVA | C10: PORCION | F10: =+E10*D10 -> 0
A12: COSTO TOTAL DE LOS INGREDIENTES | F12: =SUM(F6:F11) -> 13392.241
A13: MARGEN DE ERROR O VARIACIÓN | E13: 0 | F13: =+F12*E13 -> 0
A14: COSTO TOTAL DE LA PREPARACIÓN + MARGEN DE ERROR | F14: =+F12+F13 -> 13392.241
A15: COSTO DE UNA PORCIÓN SUMANDO EL MARGEN DE ERROR | F15: =+F14/F4 -> 13392.241
A16: % COSTO MATERIA PRIMA ESTABLECIDO POR GERENCIA | F16: 0.35
A17: PRECIO POTENCIAL DE VENTA DE UNA PORCIÓN | F17: =+F15/F16 -> 38263.546
A18: PRECIO REAL DE VENTA DE UNA PORCIÓN | F18: =ROUNDUP(F17,-2) -> 38300
A19: % REAL DE COSTO (COSTO PORCIÓN SOBRE PRECIO REAL VENTA) | F19: =+F15/F18 -> 0.34966687
A20: IVA GENERADO AL VENDER CADA PORCIÓN | E20: 0.08 | F20: =+F18*E20 -> 3064
A21: PRECIO PARA LA CARTA DE CADA PORCIÓN | F21: =+F18+F20 -> 41364
A24: POLLO CRIOLLO SALTEADO (NO SE PIDE LA PECHUGA PORCIONADA DICEN QUE LA MERMA ES MAS DE LA MITAD
A25: RECETAS ESTANDAR ALMA RURAL 2025
A26: : | E26: # RECETA | F26: 13
E27: # PORCIONES | F27: 1
A28: COD. | B28: INGREDIENTES | C28: UNID | D28: CANT. | E28: V/UNIT. | F28: V/TOTAL
B29: PECHUGA DE POLLO * 350 GR | C29: GR | D29: 400 | E29: =+'LISTA MAESTRA'!D30 -> 23.4 | F29: =E29*D29 -> 9360
B30: ARROZ PORCION | C30: PORC | D30: 1 | E30: =+'RECETA BASE'!F184 -> 685.47083 | F30: =E30*D30 -> 685.47083 | J30: 24000 | K30: =+J30/2000 -> 12 | M30: =+K30*150 -> 1800
B31: PAPAS EN CASCO | C31: PORC | D31: 1 | E31: =+'RECETA BASE'!F142 -> 2184.024 | F31: =E31*D31 -> 2184.024
B32: VINO BLANCO COCINA | C32: CC | D32: 40 | E32: =+'LISTA MAESTRA'!D115 -> 30.666667 | F32: =E32*D32 -> 1226.6667
B33: SALSA CRIOLLA | C33: PORCION | D33: 1 | E33: =+'RECETA BASE'!F252 -> 805.54906 | F33: =E33*D33 -> 805.54906 | L33: =2000/150 -> 13.333333
B34: AJONJOLI | C34: GR | D34: 10 | E34: =+'LISTA MAESTRA'!D121 -> 17.5 | F34: =E34*D34 -> 175
F35: =E35*D35 -> 0
A37: COSTO TOTAL DE LOS INGREDIENTES | F37: =SUM(F29:F36) -> 14436.711
A38: MARGEN DE ERROR O VARIACIÓN | E38: 0 | F38: =+F37*E38 -> 0
A39: COSTO TOTAL DE LA PREPARACIÓN + MARGEN DE ERROR | F39: =+F37+F38 -> 14436.711
A40: COSTO DE UNA PORCIÓN SUMANDO EL MARGEN DE ERROR | F40: =+F39/F27 -> 14436.711
A41: % COSTO MATERIA PRIMA ESTABLECIDO POR GERENCIA | F41: 0.35
A42: PRECIO POTENCIAL DE VENTA DE UNA PORCIÓN | F42: =+F40/F41 -> 41247.744
A43: PRECIO REAL DE VENTA DE UNA PORCIÓN | F43: =ROUNDUP(F42,-2) -> 41300
A44: % REAL DE COSTO (COSTO PORCIÓN SOBRE PRECIO REAL VENTA) | F44: =+F40/F43 -> 0.34955716
...

Sheet SABORES DE CERDO
A1: COSTILLAS EN SALSA BBQ
A2: RECETAS ESTANDAR ALMA RURAL 2025 | H2: LISTA MAESTRA | I2: 'RECETA BASE'
A3: : | E3: # RECETA | F3: 16
E4: # PORCIONES | F4: 1
A5: COD. | B5: INGREDIENTES | C5: UNID | D5: CANT. | E5: V/UNIT. | F5: V/TOTAL
B6: COSTILLAS DE CERDO * 500 GR | C6: GR | D6: 500 | E6: =+'LISTA MAESTRA'!D21 -> 23.6 | F6: =+E6*D6 -> 11800
B7: SALSA DE UCHUVA | C7: PORC | F7: =+E7*D7 -> 0
B8: PORCION DE ENSALADA | C8: PORCI | D8: 1 | E8: =+'RECETA BASE'!F331 -> 1020.515 | F8: =+E8*D8 -> 1020.515
B9: PAPAS EN CASCO | C9: PORCI | D9: 1 | E9: =+'RECETA BASE'!F142 -> 2184.024 | F9: =+E9*D9 -> 2184.024
B10: CARBON AL GASTO | F10: =+E10*D10 -> 0
B11: BOLSA PLASTICA | C11: UND | F11: =+E11*D11 -> 0
B12: SALSA DE ALIOLI | C12: PORCION | D12: 1 | F12: =+E12*D12 -> 0
A15: COSTO TOTAL DE LOS INGREDIENTES | F15: =SUM(F6:F14) -> 15004.539
A16: MARGEN DE ERROR O VARIACIÓN | E16: 0 | F16: =+F15*E16 -> 0
A17: COSTO TOTAL DE LA PREPARACIÓN + MARGEN DE ERROR | F17: =+F15+F16 -> 15004.539
A18: COSTO DE UNA PORCIÓN SUMANDO EL MARGEN DE ERROR | F18: =+F17/F4 -> 15004.539
A19: % COSTO MATERIA PRIMA ESTABLECIDO POR GERENCIA | F19: 0.35
A20: PRECIO POTENCIAL DE VENTA DE UNA PORCIÓN | F20: =+F18/F19 -> 42870.111
A21: PRECIO REAL DE VENTA DE UNA PORCIÓN | F21: =ROUNDUP(F20,-2) -> 42900
A22: % REAL DE COSTO (COSTO PORCIÓN SOBRE PRECIO REAL VENTA) | F22: =+F18/F21 -> 0.34975615
A23: IVA GENERADO AL VENDER CADA PORCIÓN | E23: 0.08 | F23: =+F21*E23 -> 3432
A24: PRECIO PARA LA CARTA DE CADA PORCIÓN | F24: =+F21+F23 -> 46332

Sheet TESOROS DEL RIO
A1: TRUCHA AHUMADA DE LA HUERTA
A2: RECETAS ESTANDAR ALMA RURAL 2025 | H2: LISTA MAESTRA | I2: 'RECETA BASE'
A3: : | E3: # RECETA | F3: 17
E4: # PORCIONES | F4: 1
A5: COD. | B5: INGREDIENTES | C5: UNID | D5: CANT. | E5: V/UNIT. | F5: V/TOTAL
B6: PORCION TRUCHA + 350 GR | C6: PORCION | D6: 1 | E6: =+'LISTA MAESTRA'!D14 -> 11484 | F6: =+E6*D6 -> 11484
B7: PORCION DE ENSALADA | C7: PORCION | D7: 1 | E7: =+'RECETA BASE'!F331 -> 1020.515 | F7: =+E7*D7 -> 1020.515
B8: PIMIENTA | C8: GR | D8: 2 | E8: =+'LISTA MAESTRA'!D107 -> 320 | F8: =+E8*D8 -> 640
B9: SAL | C9: GR | D9: 2 | E9: =+'LISTA MAESTRA'!D95 -> 2.4666667 | F9: =+E9*D9 -> 4.9333333
B10: ADOBO | C10: PORCIÓN | D10: 1 | E10: =+'RECETA BASE'!F314 -> 558.18413 | F10: =+E10*D10 -> 558.18413
B11: HOJA DE PLATANO | C11: UNIDAD | F11: =+E11*D11 -> 0
B12: CARBON AL GASTO | F12: =+E12*D12 -> 0
B13: PLATANO VERDE PORCION | C13: PORCION | D13: 0.5 | E13: =+'RECETA BASE'!F107 -> 4971.824 | F13: =+E13*D13 -> 2485.912
B14: PEREJIL | C14: GR | F14: =+E14*D14 -> 0
B15: TOMATE CHERRY | C15: GR | F15: =+E15*D15 -> 0
A18: COSTO TOTAL DE LOS INGREDIENTES | F18: =SUM(F6:F17) -> 16193.544
A19: MARGEN DE ERROR O VARIACIÓN | E19: 0 | F19: =+F18*E19 -> 0
A20: COSTO TOTAL DE LA PREPARACIÓN + MARGEN DE ERROR | F20: =+F18+F19 -> 16193.544
A21: COSTO DE UNA PORCIÓN SUMANDO EL MARGEN DE ERROR | F21: =+F20/F4 -> 16193.544
A22: % COSTO MATERIA PRIMA ESTABLECIDO POR GERENCIA | F22: 0.35
A23: PRECIO POTENCIAL DE VENTA DE UNA PORCIÓN | F23: =+F21/F22 -> 46267.27
A24: PRECIO REAL DE VENTA DE UNA PORCIÓN | F24: =ROUNDUP(F23,-2) -> 46300
A25: % REAL DE COSTO (COSTO PORCIÓN SOBRE PRECIO REAL VENTA) | F25: =+F21/F24 -> 0.34975258
A26: IVA GENERADO AL VENDER CADA PORCIÓN | E26: 0.08 | F26: =+F24*E26 -> 3704
A27: PRECIO PARA LA CARTA DE CADA PORCIÓN | F27: =+F24+F26 -> 50004
A30: TRUCHA A LA CRIOLLA
A31: RECETAS ESTANDAR ALMA RURAL 2025
A32: : | E32: # RECETA | F32: 18
E33: # PORCIONES | F33: 1
A34: COD. | B34: INGREDIENTES | C34: UNID | D34: CANT. | E34: V/UNIT. | F34: V/TOTAL
B35: PORCION DE TRUCHA * 350 | C35: PORCION | D35: 1 | E35: =+'LISTA MAESTRA'!D14 -> 11484 | F35: =E35*D35 -> 11484
B36: PORCION SALSA CRIOLLA | C36: PORCION | D36: 2 | E36: =+'RECETA BASE'!F252 -> 805.54906 | F36: =E36*D36 -> 1611.0981
B37: PAPAS EN CASCO | C37: PORCION | D37: 1 | E37: =+'RECETA BASE'!F143 -> 2060.4 | F37: =E37*D37 -> 2060.4
B38: MARGARINA | C38: GR | D38: 30 | E38: =+'LISTA MAESTRA'!D87 -> 17.2625 | F38: =E38*D38 -> 517.875
B39: PASTA DE AJO | C39: GR | D39: 1 | E39: =+'RECETA BASE'!F418 -> 502.5 | F39: =E39*D39 -> 502.5
B40: PIMIENTA | C40: GR | D40: 1 | E40: =+'LISTA MAESTRA'!D107 -> 320 | F40: =E40*D40 -> 320
B41: SAL | C41: GR | D41: 3 | E41: =+'LISTA MAESTRA'!D95 -> 2.4666667 | F41: =E41*D41 -> 7.4
B42: VINO BLANCO | C42: CC | D42: 30 | E42: =+'LISTA MAESTRA'!D115 -> 30.666667 | F42: =E42*D42 -> 920
F43: =E43*D43 -> 0
A44: COSTO TOTAL DE LOS INGREDIENTES | F44: =SUM(F35:F43) -> 17423.273
...

Sheet CARNE DEL CORRAL
A1: CHURRASCO DE RES
A2: RECETAS ESTANDAR ALMA RURAL 2025 | H2: LISTA MAESTRA | I2: 'RECETA BASE'
A3: : | E3: # RECETA | F3: 23
E4: # PORCIONES | F4: 1
A5: COD. | B5: INGREDIENTES | C5: UNID | D5: CANT. | E5: V/UNIT. | F5: V/TOTAL
B6: PORCION DE CHURRASCO 380 GR | C6: GR | D6: 380 | E6: =+'LISTA MAESTRA'!D7 -> 44 | F6: =+E6*D6 -> 16720
B7: PAPAS EN CASCO | C7: PORCION | D7: 1 | E7: =+'RECETA BASE'!F142 -> 2184.024 | F7: =+E7*D7 -> 2184.024
B8: ENSALADA FRESCA | C8: PORCION | D8: 1 | E8: =+'RECETA BASE'!F331 -> 1020.515 | F8: =+E8*D8 -> 1020.515
B9: ADOBO | C9: PORCION | D9: 1 | E9: =+'RECETA BASE'!F314 -> 558.18413 | F9: =+E9*D9 -> 558.18413
B10: CARBON | F10: =+E10*D10 -> 0
B11: SAL PARRILLERA | C11: GR | D11: 3 | E11: =+'LISTA MAESTRA'!D105 -> 28.157895 | F11: =+E11*D11 -> 84.473684
B12: SALSA DE ALIOLI | C12: PORCION | F12: =+E12*D12 -> 0
B13: SALSA DE UCHUVA | C13: PORCION | F13: =+E13*D13 -> 0
A15: COSTO TOTAL DE LOS INGREDIENTES | F15: =SUM(F6:F14) -> 20567.197
A16: MARGEN DE ERROR O VARIACIÓN | E16: 0 | F16: =+F15*E16 -> 0
A17: COSTO TOTAL DE LA PREPARACIÓN + MARGEN DE ERROR | F17: =+F15+F16 -> 20567.197
A18: COSTO DE UNA PORCIÓN SUMANDO EL MARGEN DE ERROR | F18: =+F17/F4 -> 20567.197
A19: % COSTO MATERIA PRIMA ESTABLECIDO POR GERENCIA | F19: 0.35
A20: PRECIO POTENCIAL DE VENTA DE UNA PORCIÓN | F20: =+F18/F19 -> 58763.419
A21: PRECIO REAL DE VENTA DE UNA PORCIÓN | F21: =ROUNDUP(F20,-2) -> 58800
A22: % REAL DE COSTO (COSTO PORCIÓN SOBRE PRECIO REAL VENTA) | F22: =+F18/F21 -> 0.34978226
A23: IVA GENERADO AL VENDER CADA PORCIÓN | E23: 0.08 | F23: =+F21*E23 -> 4704
A24: PRECIO PARA LA CARTA DE CADA PORCIÓN | F24: =+F21+F23 -> 63504
A27: PUNTA DE ANCA ASADA
A28: RECETAS ESTANDAR ALMA RURAL 2025
A29: : | E29: # RECETA | F29: 24
E30: # PORCIONES | F30: 1
A31: COD. | B31: INGREDIENTES | C31: UNID | D31: CANT. | E31: V/UNIT. | F31: V/TOTAL
B32: PORCION DE PUNTA DE ANCA 380 GR | C32: PORCION | D32: 380 | E32: =+'LISTA MAESTRA'!D6 -> 48.8 | F32: =E32*D32 -> 18544
B33: PORCION DE ENSALADA | C33: PORCION | D33: 1 | E33: =+'RECETA BASE'!F332 -> 962.75 | F33: =E33*D33 -> 962.75
B34: PAPAS EN CASCO | C34: PORCION | D34: 1 | E34: =+'RECETA BASE'!F142 -> 2184.024 | F34: =E34*D34 -> 2184.024
B35: ADOBO | C35: GR | D35: 1 | E35: =+'RECETA BASE'!F314 -> 558.18413 | F35: =E35*D35 -> 558.18413
B36: CARBON | F36: =E36*D36 -> 0
B37: SAL PARRILLERA | C37: GR | D37: 3 | E37: =+'LISTA MAESTRA'!D105 -> 28.157895 | F37: =E37*D37 -> 84.473684
B38: SALSA DE ALIOLI | C38: PORCION | F38: =E38*D38 -> 0
B39: SALSA DE UCHUVA | C39: PORCION | F39: =E39*D39 -> 0
A40: COSTO TOTAL DE LOS INGREDIENTES | F40: =SUM(F32:F39) -> 22333.432
A41: MARGEN DE ERROR O VARIACIÓN | E41: 0 | F41: =+F40*E41 -> 0
A42: COSTO TOTAL DE LA PREPARACIÓN + MARGEN DE ERROR | F42: =+F40+F41 -> 22333.432
A43: COSTO DE UNA PORCIÓN SUMANDO EL MARGEN DE ERROR | F43: =+F42/F30 -> 22333.432
...

Sheet VEGETARIANOS
A1: RAVIOLIS DE CHAMPIÑONES | P1: PROCEDIMIENTO
A2: RECETAS ESTANDAR ALMA RURAL 2025 | H2: LISTA MAESTRA | I2: 'RECETA BASE'
A3: : | E3: # RECETA | F3: 1
E4: # PORCIONES | F4: 1
A5: COD. | B5: INGREDIENTES | C5: UNID | D5: CANT. | E5: V/UNIT. | F5: V/TOTAL
B6: PORCION DE CHAMPIÑON | C6: PORCION | D6: 1 | E6: =+'RECETA BASE'!F202 -> 3239.793 | F6: =+E6*D6 -> 3239.793
B7: HARINA DE TRIGO | C7: GR | D7: 400 | E7: =+'LISTA MAESTRA'!D96 -> 3.4 | F7: =+E7*D7 -> 1360
B8: ACEITE DE OLIVA | C8: GR | D8: 60 | E8: =+'LISTA MAESTRA'!D123 -> 30.5 | F8: =+E8*D8 -> 1830
B9: HUEVOS | C9: UND | D9: 4 | E9: =+'LISTA MAESTRA'!D39 -> 433.33333 | F9: =+E9*D9 -> 1733.3333
F10: =+E10*D10 -> 0
F11: =+E11*D11 -> 0
F12: =+E12*D12 -> 0
F13: =+E13*D13 -> 0
F14: =+E14*D14 -> 0
A15: COSTO TOTAL DE LOS INGREDIENTES | F15: =SUM(F6:F14) -> 8163.1263
A16: MARGEN DE ERROR O VARIACIÓN | E16: 0 | F16: =+F15*E16 -> 0
A17: COSTO TOTAL DE LA PREPARACIÓN + MARGEN DE ERROR | F17: =+F15+F16 -> 8163.1263
A18: COSTO DE UNA PORCIÓN SUMANDO EL MARGEN DE ERROR | F18: =+F17/F4 -> 8163.1263
A19: % COSTO MATERIA PRIMA ESTABLECIDO POR GERENCIA | F19: 0.35
A20: PRECIO POTENCIAL DE VENTA DE UNA PORCIÓN | F20: =+F18/F19 -> 23323.218
A21: PRECIO REAL DE VENTA DE UNA PORCIÓN | F21: =ROUNDUP(F20,-2) -> 23400
A22: % REAL DE COSTO (COSTO PORCIÓN SOBRE PRECIO REAL VENTA) | F22: =+F18/F21 -> 0.34885155
A23: IVA GENERADO AL VENDER CADA PORCIÓN | E23: 0.08 | F23: =+F21*E23 -> 1872
A24: PRECIO PARA LA CARTA DE CADA PORCIÓN | F24: =+F21+F23 -> 25272
A27: BOWL VEGANO | P27: PROCEDIMIENTO
A28: RECETAS ESTANDAR ALMA RURAL 2025
A29: : | E29: # RECETA | F29: 1
E30: # PORCIONES | F30: 1
A31: COD. | B31: INGREDIENTES | C31: UNID | D31: CANT. | E31: V/UNIT. | F31: V/TOTAL
B32: ZANAHORIA | C32: GR | D32: 100 | E32: =+'LISTA MAESTRA'!D56 -> 5.9 | F32: =E32*D32 -> 590
B33: PIMENTON | C33: GR | D33: 100 | E33: =+'LISTA MAESTRA'!D60 -> 10.6 | F33: =E33*D33 -> 1060
B34: BROCOLI | C34: GR | D34: 100 | E34: =+'LISTA MAESTRA'!D124 -> 5.6
B35: CHAMPIÑON | C35: GR | D35: 100 | E35: =+'LISTA MAESTRA'!D40 -> 29.6 | F35: =E35*D35 -> 2960
B36: CHERRY | C36: GR | D36: 100 | F36: =E36*D36 -> 0
A38: COSTO TOTAL DE LOS INGREDIENTES | F38: =SUM(F32:F37) -> 4610
A39: MARGEN DE ERROR O VARIACIÓN | E39: 0 | F39: =+F38*E39 -> 0
A40: COSTO TOTAL DE LA PREPARACIÓN + MARGEN DE ERROR | F40: =+F38+F39 -> 4610
A41: COSTO DE UNA PORCIÓN SUMANDO EL MARGEN DE ERROR | F41: =+F40/F30 -> 4610
A42: % COSTO MATERIA PRIMA ESTABLECIDO POR GERENCIA | F42: 0.35
A43: PRECIO POTENCIAL DE VENTA DE UNA PORCIÓN | F43: =+F41/F42 -> 13171.429
...

Sheet PRESUPUESTO
B2: COSTOS OPERATIVOS COCINA | J2: ITEM
B3: NOMBRE DEL PUNTO | D3: CAFETERIA 1 | F3: PRESUPUESTO | G3: PORCENTAJE | I3: AUX | J3: 550000 | K3: V
B4: COSTOS FIJO | F4: ARRIENDO | G4: =+C5/C19 -> 0.3818182 | I4: AXU COCINA | J4: 540000
B5: ARRIENDO | C5: 1200000 | F5: NOMINA | G5: =+C6/C19 -> 0.73500003 | I5: FRITURAS | J5: 220000
B6: NOMINA | C6: =+J10 -> 2310000 | F6: SERVICIOS | G6: =+SUM(C7+C10+C11+C12)/C19 -> 0.21954546 | I6: STEWARD | J6: 200000
B7: INTERNET | F7: MATERIA PRIMA | G7: 0.4 | I7: MESERO SABADO | J7: 400000
F8: UTILIDAD BRUTA (ingresos - costos) | G8: =+C21/C19 -> -0.97272736 | I8: MESERO DOMINGO 1 | J8: 200000
B9: COSTOS VARIABLES | G9: =SUM(G4:G8) -> 0.76363633 | I9: MESERO DOMINGO 2 | J9: 200000
B10: LUZ | C10: 500000 | J10: =SUM(J3:J9) -> 2310000
B11: AGUA
B12: GAS | C12: 190000 | I12: INVERSIÓN TOTAL
B13: MATERIA PRIMA | C13: 2000000 | F13: PROYECCIÓN VENTA MENSUAL | G13: =+C17 -> 6200000 | I13: MESES
B14: GASTOS OPERATIVOS | I14: CUOTA MENSUAL | J14: =+J12/J13 -> #DIV/0!
B15: RECUPERACIÓN DE LA INVERSIÓN MENSUAL
B17: TOTAL COSTOS OPERATIVOS (fijos y variables) | C17: =+SUM(C5+C6+C7+C10+C11+C12+C13+C16) -> 6200000 | G17: =+G14*8 -> 0
B18: VENTAS MENSUALES
C19: 3142857
F20: =+C13/G7 -> 5000000
B21: DIFERENCIA | C21: =+C19-C17 -> -3057143

Sheet SALSA DE AJO
B2: PROCEDIMIENTO SALSA DE AJO
B3: Preparación con Licuadora Prepara los ingredientes: Pela los dientes de ajo por la mitad y saca el germen para reducir el amargo del ajo Combina los ingredientes base: En el vaso de la licuadora, añade el huevo, la mostaza, el ajo, la sal y la pimienta. Inicia el licuado: Coloca la tapa de la licuadora, asegurándote de que la abertura superior para verter esté abierta. Enciende la licuadora a velocidad media-baja para empezar a mezclar los ingredientes. Añade el aceite lentamente: Con la licuadora funcionando, comienza a verter el aceite en un chorro muy fino y constante a través de la abertura de la tapa. Es crucial que lo hagas lentamente para que la mezcla emulsione correctamente. Observa la consistencia: Continúa vertiendo el aceite hasta que la salsa comience a espesarse y adquiera la consistencia deseada. Si notas que se está volviendo demasiado espesa, puedes detenerte antes de usar todo el aceite. Si la quieres más líquida, puedes añadir un poco de agua o leche al final. yo recomiendo crema de leche. Prueba y ajusta: Una vez que la salsa esté lista, detén la licuadora, pruébala y ajusta la sal o la pimienta si es necesario. Si quieres más sabor a ajo, puedes triturar un diente de ajo extra en un mortero y agregarlo a la salsa ya terminada. Consejos Adicionales Temperatura: , es mejor si todos los ingredientes están a temperatura ambiente para una mejor emulsión. Velocidad: Es importante comenzar con una velocidad baja para que la mezcla se combine bien antes de aumentar la velocidad. Volumen: Un litro es una cantidad grande para una licuadora doméstica. Asegúrate de que el vaso de tu licuadora tenga la capacidad suficiente. Si no es así, puedes hacer la receta en dos tandas.

Sheet REDUCCIÓN BALSAMICO
B2: PROCEDIMIENTO BALSAMICO
B3: Paso a Paso para la Reducción Combina los ingredientes: Vierte el vinagre balsámico en una olla o sartén antiadherente de fondo grueso. Azúcar, añádela ahora y revuelve hasta que se disuelva. Lleva a ebullición: Calienta la mezcla a fuego medio-alto hasta que comience a hervir. Reduce el fuego y cocina a fuego lento: Una vez que hierva, baja el fuego a medio-bajo. La mezcla debe mantenerse en un hervor suave y constante. No la tapes. Monitorea la reducción: Este es el paso más importante. El proceso puede tomar entre 15 y 30 minutos, dependiendo del tamaño de la olla y la intensidad del fuego. Observa la consistencia: Al principio se verá muy líquida. A medida que el líquido se evapore, la consistencia cambiará. cuando la preparación no este acida agregar un gramo de cmc para mejorar la consistencia. Haz la prueba de la cuchara: Saca una cuchara y sumérgela en la reducción. Si la retiras y la reducción cubre la parte de atrás de la cuchara sin gotear rápidamente, está lista. Ten cuidado de no sobre-reducir: La reducción de vinagre balsámico se volverá mucho más espesa una vez que se enfríe. Es mejor retirarla del fuego un poco antes de lo que crees que está lista. Retira del fuego y enfría: Quita la olla del calor. . Deja que la reducción se enfríe completamente antes de almacenarla. Al enfriarse, se espesará hasta alcanzar la consistencia de un jarabe. Almacena: Vierte la reducción en una botella o recipiente hermético. Guárdala en un lugar fresco y oscuro, como una despensa. No es necesario refrigerarla.

Sheet MIEL DE JENGIBRE
B2: MIEL DE GENGIBRE
B3: EN LA MIEL AGREGAR EL GENGIBRE Y EL LIMONCILLO Y DEJAR REPOSAR POR 3 DIAS, EL GENGIBRE SE DEBE AGREGAR SIN PIEL

Sheet DE LA CASA
B2: SALSA DE LA CASA
B3: Procedimiento (Paso a Paso) Prepara los ingredientes secos: En un tazón mediano, mezcla el ajo en polvo, las dos pimientas y la páprika. Revolver bien te ayudará a evitar grumos. Combina la base líquida: En un recipiente grande (o en el vaso de una licuadora), agrega la mayonesa, la salsa de tomate y la salsa inglesa. Integra todos los ingredientes: Añade la mezcla de especias secas al recipiente con los ingredientes húmedos. Mezcla hasta homogeneizar: Con la ayuda de, una licuadora, mezcla todos los ingredientes hasta obtener una salsa de color uniforme y sin grumos. Prueba y ajusta: Una vez que la salsa esté bien mezclada, pruébala. Puedes ajustar la cantidad de cada ingrediente según tus preferencias personales. Por ejemplo, si la quieres más dulce, agrega un poco más de salsa de tomate; si buscas un sabor más profundo y salado, añade más salsa inglesa. Notas Adicionales Consistencia: La mayonesa es la que define la consistencia de esta salsa. Si quieres una salsa más líquida, puedes agregar un poco de agua o leche al gusto. Almacenamiento: Vierte la salsa en un recipiente hermético. Esta salsa se conserva bien refrigerada por 5 a 7 días. Variantes: Puedes usar páprika ahumada para darle un toque diferente o añadir un poco de cebolla en polvo para un sabor más complejo.
